Workbook

Sheet Overview
A1: NJ Youth Football Master Inventory
A3: Purpose
A4: Working statewide inventory for NJYASA/GIS research. It separates league governance from local organizations, tracks season-specific affiliations, and preserves uncertainty instead of treating all affiliations as permanent.
A7: Inventory Snapshot
A8: Current/recent league systems in working inventory | B8: 18
A9: Historical/status-to-verify systems retained | B9: 1
A10: New Jersey counties in proposed model | B10: 21
A11: NJYASA regions | B11: 3
A12: Organization records entered in v1 | B12: 213
A15: Important methodology note
A16: This is a versioned research inventory, not a claim that every row is permanent or exhaustive. Youth programs change leagues, merge, split, and use different age-level affiliations. Use Season, Evidence Status, and Source fields before drawing conclusions.
A20: Color key
A21: Imported / linked source data
A22: Static/reference values
A23: Review / incomplete / caution
A24: Potential error / unresolved
A25: Logic / classification
A27: Phase 1 update - 2026 affiliation cleanup started
A28: • Added Program Master and Affiliation History so one program can change leagues without being duplicated as a new identity.
A29: • Initial Phase 1 audit corrected Franklin Lakes (current NBJFL; prior TCYFL), separated Vineland Youth Football/TCUFL from Vineland Blitz/CAJFL, and added current TCUFL/CAJFL programs found in official directories.
A30: • Conflicting 2026 sources for Burlington City and Rancocas Valley are preserved and flagged rather than silently choosing one directory over another; current SJIYFA schedules provide direct current-season evidence.
... A34: Municipality Cleanup sheet was added as a county-by-county review layer. Original Municipality_or_Area fields remain unchanged until normalization is complete.

Sheet Phase 1 Control
A1: Phase 1 - Organization Inventory
A2: Goal: identify each program once, verify its current league affiliation, preserve affiliation history, and flag conflicts before adding geographic service-area data.
A4: Phase 1 snapshot
A5: Provisional unique program identities | B5: =COUNTA('Program Master'!$A:$A)-3 | C5: Exact-name + county identity rule; still subject to manual merge/split review.
A6: Programs with current supported affiliation | B6: =COUNTIF('Program Master'!$F:$F,"Current") | C6: At least one current affiliation is supported.
A7: Programs requiring current-status verification | B7: =COUNTIF('Program Master'!$F:$F,"Current status to verify") | C7: Conflicting or partial current evidence.
A8: Historical-only program identities | B8: =COUNTIF('Program Master'!$F:$F,"Historical / no current affiliation verified") | C8: Retained for history but not counted as current.
A9: Multiple-current-affiliation flags | B9: =COUNTIF('Program Master'!$J:$J,"MULTIPLE CURRENT AFFILIATIONS*") | C9: Could be split teams/levels, a real dual affiliation, or stale source data.
A11: Evidence order used in Phase 1
A12: 1 | B12: Current-season league schedule / standings / roster | C12: Strongest for actual current competitive affiliation.
A13: 2 | B13: Current official program site explicitly naming league | C13: Strong corroboration for current affiliation.
A14: 3 | B14: Current league team/member directory | C14: Useful, but can lag realignment or transfers.
A15: 4 | B15: Older bylaws, archived schedules, historical pages | C15: Keep for affiliation history, not current status without corroboration.
A16: 5 | B16: Direct user knowledge | C16: Useful lead; where possible corroborate with a public current-season source for research use.
A19: League_ID | B19: League_Name | C19: Membership_List_Status | D19: Exact_Current_Status | E19: Current_Program_Records | F19: Verify_Program_Records | G19: Phase1_Priority | H19: Phase1_State | I19: Next_Action | J19: Notes | K19: Source_Focus | L19: Batch
A20: L001 | B20: South Jersey Independent Youth Football Association | C20: Partial | D20: Yes | E20: =COUNTIFS('Affiliation History'!$D:$D,A20,'Affiliation History'!$K:$K,"Yes") | F20: =COUNTIFS('Affiliation History'!$D:$D,A20,'Affiliation History'!$K:$K,"Verify") | G20: High | H20: Membership/current-season verification incomplete | I20: Complete organization membership and player-count fields. | K20: Prefer current schedule/roster over static directory when sources conflict. | L20: South - initial audit
A21: L002 | B21: Tri-County United Football League | C21: Yes | D21: Yes | E21: =COUNTIFS('Affiliation History'!$D:$D,A21,'Affiliation History'!$K:$K,"Yes") | F21: =COUNTIFS('Affiliation History'!$D:$D,A21,'Affiliation History'!$K:$K,"Verify") | G21: Medium | H21: Current list located | I21: Complete organization membership and player-count fields. | J21: 2026 TCUFL directory conflicts with current SJIYFA schedule for Burlington City and Rancocas Valley. | K21: Prefer current schedule/roster over static directory when sources conflict. | L21: South - initial audit
A22: L003 | B22: West Jersey Youth Football League | C22: Partial | D22: Yes | E22: =COUNTIFS('Affiliation History'!$D:$D,A22,'Affiliation History'!$K:$K,"Yes") | F22: =COUNTIFS('Affiliation History'!$D:$D,A22,'Affiliation History'!$K:$K,"Verify") | G22: High | H22: Membership/current-season verification incomplete | I22: Locate current membership, territory, and field documentation. | K22: Prefer current schedule/roster over static directory when sources conflict. | L22: South - initial audit
A23: L004 | B23: Cape Atlantic Junior Football League | C23: Partial | D23: Yes | E23: =COUNTIFS('Affiliation History'!$D:$D,A23,'Affiliation History'!$K:$K,"Yes") | F23: =COUNTIFS('Affiliation History'!$D:$D,A23,'Affiliation History'!$K:$K,"Verify") | G23: High | H23: Membership/current-season verification incomplete | I23: Collect/standardize organization-level roster counts and field coordinates. | J23: Hamilton Knights added; Wildwood is field-listed but exact 2026 competitive membership still needs confirmation. | K23: Prefer current schedule/roster over static directory when sources conflict. | L23: South - initial audit
A24: L005 | B24: Jersey Shore Youth Football League | C24: Yes | D24: Partial | E24: =COUNTIFS('Affiliation History'!$D:$D,A24,'Affiliation History'!$K:$K,"Yes") | F24: =COUNTIFS('Affiliation History'!$D:$D,A24,'Affiliation History'!$K:$K,"Verify") | G24: High | H24: Membership/current-season verification incomplete | I24: Collect/standardize organization-level roster counts and field coordinates. | K24: Prefer current schedule/roster over static directory when sources conflict. | L24: South - initial audit
A25: L006 | B25: New Jersey American Youth Football - Jersey Shore Conference | C25: Partial | D25: Yes | E25: =COUNTIFS('Affiliation History'!$D:$D,A25,'Affiliation History'!$K:$K,"Yes") | F25: =COUNTIFS('Affiliation History'!$D:$D,A25,'Affiliation History'!$K:$K,"Verify") | G25: High | H25: Membership/current-season verification incomplete | I25: Collect/standardize organization-level roster counts and field coordinates. | K25: Prefer current schedule/roster over static directory when sources conflict. | L25: Pending
A26: L007 | B26: New Jersey Suburban Youth Football League | C26: Yes | D26: Yes | E26: =COUNTIFS('Affiliation History'!$D:$D,A26,'Affiliation History'!$K:$K,"Yes") | F26: =COUNTIFS('Affiliation History'!$D:$D,A26,'Affiliation History'!$K:$K,"Verify") | G26: Medium | H26: Current list located | I26: Complete organization membership and player-count fields. | K26: Prefer current schedule/roster over static directory when sources conflict. | L26: Pending
A27: L008 | B27: Morris County Youth Football League | C27: Partial | D27: Yes | E27: =COUNTIFS('Affiliation History'!$D:$D,A27,'Affiliation History'!$K:$K,"Yes") | F27: =COUNTIFS('Affiliation History'!$D:$D,A27,'Affiliation History'!$K:$K,"Verify") | G27: High | H27: Membership/current-season verification incomplete | I27: Collect/standardize organization-level roster counts and field coordinates. | K27: Prefer current schedule/roster over static directory when sources conflict. | L27: Pending
A28: L009 | B28: Meadowlands Football League | C28: Partial | D28: Yes | E28: =COUNTIFS('Affiliation History'!$D:$D,A28,'Affiliation History'!$K:$K,"Yes") | F28: =COUNTIFS('Affiliation History'!$D:$D,A28,'Affiliation History'!$K:$K,"Verify") | G28: High | H28: Membership/current-season verification incomplete | I28: Complete organization membership and player-count fields. | K28: Prefer current schedule/roster over static directory when sources conflict. | L28: Pending
A29: L010 | B29: Northern Bergen Junior Football League | C29: Partial | D29: Yes | E29: =COUNTIFS('Affiliation History'!$D:$D,A29,'Affiliation History'!$K:$K,"Yes") | F29: =COUNTIFS('Affiliation History'!$D:$D,A29,'Affiliation History'!$K:$K,"Verify") | G29: High | H29: Membership/current-season verification incomplete | I29: Collect/standardize organization-level roster counts and field coordinates. | K29: Prefer current schedule/roster over static directory when sources conflict. | L29: North/Central follow-up
A30: L011 | B30: Bergen County Junior Football League | C30: Yes | D30: Yes | E30: =COUNTIFS('Affiliation History'!$D:$D,A30,'Affiliation History'!$K:$K,"Yes") | F30: =COUNTIFS('Affiliation History'!$D:$D,A30,'Affiliation History'!$K:$K,"Verify") | G30: Medium | H30: Current list located | I30: Locate current membership, territory, and field documentation. | K30: Prefer current schedule/roster over static directory when sources conflict. | L30: Pending
A31: L012 | B31: Tri-County Youth Football League - Northern NJ | C31: Yes | D31: Yes | E31: =COUNTIFS('Affiliation History'!$D:$D,A31,'Affiliation History'!$K:$K,"Yes") | F31: =COUNTIFS('Affiliation History'!$D:$D,A31,'Affiliation History'!$K:$K,"Verify") | G31: Medium | H31: Current list located | I31: Complete organization membership and player-count fields. | J31: Franklin Lakes corrected to historical TCYFL affiliation; 2026 NBJFL roster confirms current NBJFL affiliation. | K31: Prefer current schedule/roster over static directory when sources conflict. | L31: North/Central follow-up
A32: L013 | B32: North Jersey Pop Warner | C32: Partial | D32: Yes | E32: =COUNTIFS('Affiliation History'!$D:$D,A32,'Affiliation History'!$K:$K,"Yes") | F32: =COUNTIFS('Affiliation History'!$D:$D,A32,'Affiliation History'!$K:$K,"Verify") | G32: High | H32: Membership/current-season verification incomplete | I32: Complete organization membership and player-count fields. | K32: Prefer current schedule/roster over static directory when sources conflict. | L32: Pending
A33: L014 | B33: Central Jersey Pop Warner | C33: Yes | D33: Yes | E33: =COUNTIFS('Affiliation History'!$D:$D,A33,'Affiliation History'!$K:$K,"Yes") | F33: =COUNTIFS('Affiliation History'!$D:$D,A33,'Affiliation History'!$K:$K,"Verify") | G33: Medium | H33: Current list located | I33: Complete organization membership and player-count fields. | K33: Prefer current schedule/roster over static directory when sources conflict. | L33: Pending
A34: L015 | B34: New Jersey Shore Pop Warner | C34: Yes | D34: Yes | E34: =COUNTIFS('Affiliation History'!$D:$D,A34,'Affiliation History'!$K:$K,"Yes") | F34: =COUNTIFS('Affiliation History'!$D:$D,A34,'Affiliation History'!$K:$K,"Verify") | G34: Medium | H34: Current list located | I34: Complete organization membership and player-count fields. | K34: Prefer current schedule/roster over static directory when sources conflict. | L34: Pending
A35: L016 | B35: Newark Pop Warner | C35: Partial | D35: Yes | E35: =COUNTIFS('Affiliation History'!$D:$D,A35,'Affiliation History'!$K:$K,"Yes") | F35: =COUNTIFS('Affiliation History'!$D:$D,A35,'Affiliation History'!$K:$K,"Verify") | G35: High | H35: Membership/current-season verification incomplete | I35: Locate current membership, territory, and field documentation. | K35: Prefer current schedule/roster over static directory when sources conflict. | L35: Pending
A36: L017 | B36: Bi-County Junior Scholastic Football League | C36: Older/uncertain | D36: No/older | E36: =COUNTIFS('Affiliation History'!$D:$D,A36,'Affiliation History'!$K:$K,"Yes") | F36: =COUNTIFS('Affiliation History'!$D:$D,A36,'Affiliation History'!$K:$K,"Verify") | G36: High | H36: Historical/current status unresolved | I36: Complete organization membership and player-count fields. | K36: Prefer current schedule/roster over static directory when sources conflict. | L36: Pending
A37: L018 | B37: West Essex Junior Football League | C37: Partial | D37: Yes | E37: =COUNTIFS('Affiliation History'!$D:$D,A37,'Affiliation History'!$K:$K,"Yes") | F37: =COUNTIFS('Affiliation History'!$D:$D,A37,'Affiliation History'!$K:$K,"Verify") | G37: High | H37: Membership/current-season verification incomplete | I37: Locate current membership, territory, and field documentation. | K37: Prefer current schedule/roster over static directory when sources conflict. | L37: Pending
A38: L019 | B38: Atlantic County Junior Football League | C38: Older/uncertain | D38: No/older | E38: =COUNTIFS('Affiliation History'!$D:$D,A38,'Affiliation History'!$K:$K,"Yes") | F38: =COUNTIFS('Affiliation History'!$D:$D,A38,'Affiliation History'!$K:$K,"Verify") | G38: High | H38: Historical/current status unresolved | I38: Locate current membership, territory, and field documentation. | K38: Prefer current schedule/roster over static directory when sources conflict. | L38: Pending

Sheet Program Master
A1: Program Master
A2: Phase 1: one provisional identity per youth football program. Affiliations are separated from program identity so league changes can be tracked over time.
A3: Program_ID | B3: Canonical_Program_Name | C3: Primary_County | D3: Municipality_or_Area | E3: NJYASA_Region | F3: Current_Status | G3: Current_League_IDs | H3: Current_League_Names | I3: Current_Affiliation_Count | J3: Current_Affiliation_Review | K3: Historical_or_Prior_Leagues | L3: Football_Format | M3: Age_or_Grade_Levels | N3: Program_Scope | O3: Phase1_Verification | P3: Notes
A4: P001 | B4: Mo Better Jaguars | D4: Mo Better Jaguars | F4: Current status to verify | I4: 0 | J4: Current source conflict / partial evidence | N4: To classify | O4: Current source conflict / partial evidence | P4: Verify-listed league(s): L013
A5: P002 | B5: Absecon Blue Devils | C5: Atlantic | D5: Absecon Blue Devils | E5: South | F5: Current | G5: L005 | H5: Jersey Shore Youth Football League | I5: 1 | J5: Current affiliation supported | N5: To classify | O5: Current affiliation supported
A6: P003 | B6: Atlantic City | C6: Atlantic | D6: Atlantic City | E6: South | F6: Current | G6: L002 | H6: Tri-County United Football League | I6: 1 | J6: Current affiliation supported | N6: To classify | O6: Current affiliation supported
A7: P004 | B7: Brigantine Rams | C7: Atlantic | D7: Brigantine Rams | E7: South | F7: Current | G7: L005 | H7: Jersey Shore Youth Football League | I7: 1 | J7: Current affiliation supported | N7: To classify | O7: Current affiliation supported
A8: P005 | B8: Buena | C8: Atlantic | D8: Buena | E8: South | F8: Current | G8: L005 | H8: Jersey Shore Youth Football League | I8: 1 | J8: Current affiliation supported | N8: To classify | O8: Current affiliation supported
A9: P006 | B9: Egg Harbor City | C9: Atlantic | D9: Egg Harbor City | E9: South | F9: Current | G9: L005 | H9: Jersey Shore Youth Football League | I9: 1 | J9: Current affiliation supported | N9: To classify | O9: Current affiliation supported
A10: P007 | B10: Egg Harbor Township | C10: Atlantic | D10: Egg Harbor Township | E10: South | F10: Current | G10: L004 | H10: Cape Atlantic Junior Football League | I10: 1 | J10: Current affiliation supported | N10: To classify | O10: Current affiliation supported
A11: P008 | B11: Egg Harbor Township / EHTYO | C11: Atlantic | D11: Egg Harbor Township / EHTYO | E11: South | F11: Current | G11: L005 | H11: Jersey Shore Youth Football League | I11: 1 | J11: Current affiliation supported | N11: To classify | O11: Current affiliation supported
A12: P009 | B12: Galloway | C12: Atlantic | D12: Galloway | E12: South | F12: Current | G12: L004 | H12: Cape Atlantic Junior Football League | I12: 1 | J12: Current affiliation supported | N12: To classify | O12: Current affiliation supported
A13: P010 | B13: Hamilton Knights | C13: Atlantic | D13: Hamilton Township / Mays Landing area | E13: South | F13: Current | G13: L004 | H13: Cape Atlantic Junior Football League | I13: 1 | J13: Current affiliation supported | N13: To classify | O13: Current affiliation supported
A14: P011 | B14: Hammonton Hawks | C14: Atlantic | D14: Hammonton Hawks | E14: South | F14: Current | G14: L005 | H14: Jersey Shore Youth Football League | I14: 1 | J14: Current affiliation supported | N14: To classify | O14: Current affiliation supported
A15: P012 | B15: Linwood Panthers | C15: Atlantic | D15: Linwood Panthers | E15: South | F15: Current | G15: L005 | H15: Jersey Shore Youth Football League | I15: 1 | J15: Current affiliation supported | N15: To classify | O15: Current affiliation supported
A16: P013 | B16: Mays Landing | C16: Atlantic | D16: Mays Landing | E16: South | F16: Current | G16: L002 | H16: Tri-County United Football League | I16: 1 | J16: Current affiliation supported | N16: To classify | O16: Current affiliation supported
... A20: P017 | B20: Ventnor Pirates | C20: Atlantic | D20: Ventnor Pirates | E20: South | F20: Current | G20: L005 | H20: Jersey Shore Youth Football League | I20: 1 | J20: Current affiliation supported | N20: To classify | O20: Current affiliation supported
A21: P018 | B21: Bergenfield | C21: Bergen | D21: Bergenfield | E21: North | F21: Current | G21: L011 | H21: Bergen County Junior Football League | I21: 1 | J21: Current affiliation supported | K21: L017 | N21: To classify | O21: Current affiliation supported
A22: P019 | B22: Bogota | C22: Bergen | D22: Bogota | E22: North | F22: Historical / no current affiliation verified | I22: 0 | J22: Needs 2026 current-status verification | K22: L017 | N22: To classify | O22: Needs 2026 current-status verification
A23: P020 | B23: Carlstadt / East Rutherford | C23: Bergen | D23: Carlstadt / East Rutherford | E23: North | F23: Current | G23: L011 | H23: Bergen County Junior Football League | I23: 1 | J23: Current affiliation supported | N23: To classify | O23: Current affiliation supported
A24: P021 | B24: Cliffside Park / Ridgefield | C24: Bergen | D24: Cliffside Park / Ridgefield | E24: North | F24: Historical / no current affiliation verified | I24: 0 | J24: Needs 2026 current-status verification | K24: L017 | N24: To classify | O24: Needs 2026 current-status verification
A25: P022 | B25: Cresskill | C25: Bergen | D25: Cresskill | E25: North | F25: Current | G25: L011 | H25: Bergen County Junior Football League | I25: 1 | J25: Current affiliation supported | N25: To classify | O25: Current affiliation supported
A26: P023 | B26: Dumont | C26: Bergen | D26: Dumont | E26: North | F26: Current | G26: L011 | H26: Bergen County Junior Football League | I26: 1 | J26: Current affiliation supported | N26: To classify | O26: Current affiliation supported
A27: P024 | B27: Elmwood Park | C27: Bergen | D27: Elmwood Park | E27: North | F27: Current | G27: L009 | H27: Meadowlands Football League | I27: 1 | J27: Current affiliation supported | N27: To classify | O27: Current affiliation supported
A28: P025 | B28: Englewood / Englewood Cliffs | C28: Bergen | D28: Englewood / Englewood Cliffs | E28: North | F28: Historical / no current affiliation verified | I28: 0 | J28: Needs 2026 current-status verification | K28: L017 | N28: To classify | O28: Needs 2026 current-status verification
A29: P026 | B29: Fair Lawn | C29: Bergen | D29: Fair Lawn | E29: North | F29: Current | G29: L010 | H29: Northern Bergen Junior Football League | I29: 1 | J29: Current affiliation supported | N29: To classify | O29: Current affiliation supported
A30: P027 | B30: Fort Lee / Edgewater | C30: Bergen | D30: Fort Lee / Edgewater | E30: North | F30: Historical / no current affiliation verified | I30: 0 | J30: Needs 2026 current-status verification | K30: L017 | N30: To classify | O30: Needs 2026 current-status verification
A31: P028 | B31: Franklin Lakes | C31: Bergen | D31: Franklin Lakes | E31: North | F31: Current | G31: L010 | H31: Northern Bergen Junior Football League | I31: 1 | J31: Current affiliation supported | K31: L012 | N31: To classify | O31: Current affiliation supported
A32: P029 | B32: Garfield | C32: Bergen | D32: Garfield | E32: North | F32: Current | G32: L011 | H32: Bergen County Junior Football League | I32: 1 | J32: Current affiliation supported | N32: To classify | O32: Current affiliation supported
A33: P030 | B33: Glen Rock | C33: Bergen | D33: Glen Rock | E33: North | F33: Current | G33: L012 | H33: Tri-County Youth Football League - Northern NJ | I33: 1 | J33: Current affiliation supported | N33: To classify | O33: Current affiliation supported
A34: P031 | B34: Hasbrouck Heights | C34: Bergen | D34: Hasbrouck Heights | E34: North | F34: Current | G34: L009 | H34: Meadowlands Football League | I34: 1 | J34: Current affiliation supported | N34: To classify | O34: Current affiliation supported
A35: P032 | B35: Hillsdale | C35: Bergen | D35: Hillsdale | E35: North | F35: Current | G35: L011 | H35: Bergen County Junior Football League | I35: 1 | J35: Current affiliation supported | N35: To classify | O35: Current affiliation supported
A36: P033 | B36: Little Ferry / Ridgefield Park | C36: Bergen | D36: Little Ferry / Ridgefield Park | E36: North | F36: Historical / no current affiliation verified | I36: 0 | J36: Needs 2026 current-status verification | K36: L017 | N36: To classify | O36: Needs 2026 current-status verification
A37: P034 | B37: Lodi | C37: Bergen | D37: Lodi | E37: North | F37: Historical / no current affiliation verified | I37: 0 | J37: Needs 2026 current-status verification | K37: L017 | N37: To classify | O37: Needs 2026 current-status verification
A38: P035 | B38: Lyndhurst | C38: Bergen | D38: Lyndhurst | E38: North | F38: Current | G38: L009 | H38: Meadowlands Football League | I38: 1 | J38: Current affiliation supported | N38: To classify | O38: Current affiliation supported
A39: P036 | B39: Mahwah | C39: Bergen | D39: Mahwah | E39: North | F39: Current | G39: L010 | H39: Northern Bergen Junior Football League | I39: 1 | J39: Current affiliation supported | N39: To classify | O39: Current affiliation supported
A40: P037 | B40: New Milford | C40: Bergen | D40: New Milford | E40: North | F40: Current | G40: L009 | H40: Meadowlands Football League | I40: 1 | J40: Current affiliation supported | N40: To classify | O40: Current affiliation supported
A41: P038 | B41: North Arlington | C41: Bergen | D41: North Arlington | E41: North | F41: Current | G41: L009 | H41: Meadowlands Football League | I41: 1 | J41: Current affiliation supported | N41: To classify | O41: Current affiliation supported
A42: P039 | B42: Northern Highlands | C42: Bergen | D42: Northern Highlands | E42: North | F42: Current | G42: L010 | H42: Northern Bergen Junior Football League | I42: 1 | J42: Current affiliation supported | N42: To classify | O42: Current affiliation supported
A43: P040 | B43: Northern Valley | C43: Bergen | D43: Northern Valley | E43: North | F43: Current | G43: L011 | H43: Bergen County Junior Football League | I43: 1 | J43: Current affiliation supported | N43: To classify | O43: Current affiliation supported
...

Sheet Municipality Cleanup
A1: Municipality Cleanup - Foundational Inventory V1
A2: Working review sheet. Primary municipality is assigned from the current program home field / primary operating location when available. Original Municipality_or_Area is preserved for context.
A3: Program_ID | B3: Organization | C3: Current_League | D3: County | E3: Existing_Municipality_or_Area | F3: Home_Field | G3: Field_Address | H3: Primary_Municipality | I3: Verification_Basis | J3: League_Source_URL | K3: Municipality_Verification_URL | L3: Review_Status
A4: P055 | B4: Bordentown | C4: West Jersey Youth Football League | D4: Burlington | E4: Bordentown | F4: Bordentown Bulldogs | G4: 50 Dunns Mill Rd., Bordentown, NJ | H4: Bordentown Township | I4: Primary home field at 50 Dunns Mill Rd is in Bordentown Township. | J4: https://www.westjerseyyouthfootball.com/teams | K4: https://www.co.burlington.nj.us/DocumentCenter/View/2405 | L4: Ready
A5: P056 | B5: Burlington City | C5: South Jersey Independent Youth Football Association | D5: Burlington | E5: Burlington City | F5: Burlington City | G5: 550 High St, Burlington, NJ 08016 | H5: Burlington City | I5: Current SJIYFA field is 550 High St; official Burlington City school information identifies that address in Burlington City. | J5: https://www.sjiyfa.org/schedule.php?group=2&township=0&type=0&week=0&weight=0 | K5: https://www.burlington-nj.net/apps/pages/index.jsp?pREC_ID=1173434&termREC_ID=&type=d&uREC_ID=613587 | L5: Ready
A6: P057 | B6: Florence | C6: West Jersey Youth Football League | D6: Burlington | E6: Florence | F6: Florence Flashes | G6: 875 Summer St., Florence, NJ | H6: Florence Township | I6: Primary field address is 875 Summer St; Florence Township identifies 875 Summer Street as a township facility. | J6: https://www.westjerseyyouthfootball.com/teams | K6: https://florence-nj.gov/departments/public-works/recycling-information/florence-twp-recycling-center/ | L6: Ready
A7: P058 | B7: Moorestown | C7: West Jersey Youth Football League | D7: Burlington | E7: Moorestown | F7: Moorestown Junior Quakers | G7: 1248 N. Church St., Moorestown, NJ | H7: Moorestown Township | I7: Primary field address is 1248 N Church St; Moorestown municipal records identify 1248 N Church St as Township property/open space. | J7: https://www.westjerseyyouthfootball.com/teams | K7: https://www.moorestown.nj.us/DocumentCenter/View/5693/2018282901_Affordable_Housing_Settlement_Agreement_2018 | L7: Ready
A8: P059 | B8: Northern Burlington | C8: West Jersey Youth Football League | D8: Burlington | E8: Northern Burlington | F8: Northern Burlington Greyhounds | G8: 180/160 Mansfield Rd., East Mansfield, NJ | H8: Mansfield Township | I8: Northern Burlington school complex at 160 Mansfield Rd is identified by Burlington County as being in Mansfield Township. | J8: https://www.westjerseyyouthfootball.com/teams | K8: https://www.co.burlington.nj.us/DocumentCenter/Home/View/852 | L8: Ready
A9: P060 | B9: Palmyra | C9: West Jersey Youth Football League | D9: Burlington | E9: Palmyra | F9: Palmyra Panthers | G9: Broad & Park Ave., Palmyra, NJ | H9: Palmyra Borough | I9: Program is based in Palmyra; NJ municipal records identify the legal municipality as Palmyra Borough. | J9: https://www.westjerseyyouthfootball.com/teams | K9: https://www.nj.gov/cgi-bin/dhss/vital/registrars.pl?county=Burlington | L9: Ready
A10: P061 | B10: Pemberton | C10: West Jersey Youth Football League | D10: Burlington | E10: Pemberton | F10: Pemberton Hornets | G10: 1 Anderson Rd., Pemberton, NJ | H10: Pemberton Township | I10: Primary field is 1 Anderson Rd / Nesbit Center; Burlington County polling records identify it as Pemberton Township. | J10: https://www.westjerseyyouthfootball.com/teams | K10: https://nj-burlingtoncounty.civicplus.com/DocumentCenter/View/21568/Primary-2025-Polling-Locations-PDF | L10: Ready
A11: P062 | B11: Rancocas Valley Hurricanes | C11: South Jersey Independent Youth Football Association | D11: Burlington | E11: Rancocas Valley / Lumberton area | F11: Lumberton Field / RVHS | G11: 35 Municipal Dr., Lumberton, NJ 08048 | H11: Lumberton Township | I11: Primary field/operating location is 35 Municipal Dr; Lumberton Township identifies this address as its municipal complex. | J11: https://www.sjiyfa.org/schedule.php?group=2&township=0&type=0&week=0&weight=0 | K11: https://www.lumbertontwp.com/contact-us/ | L11: Ready
A12: P063 | B12: Riverside | C12: West Jersey Youth Football League | D12: Burlington | E12: Riverside | F12: Riverside Rams | G12: 112 E. Washington St., Riverside, NJ | H12: Riverside Township | I12: Primary field is 112 E Washington St; Riverside Township School District uses that same address. | J12: https://www.westjerseyyouthfootball.com/teams | K12: https://www.riverside.k12.nj.us/accessibility | L12: Ready
A13: P064 | B13: Willingboro | C13: Tri-County United Football League | D13: Burlington | E13: Willingboro | H13: Willingboro Township | I13: Program is based in Willingboro; official municipal website identifies the legal municipality as Willingboro Township. | J13: https://tcufl.org/organizations.php | K13: https://www.willingboronj.gov/ | L13: Ready

Sheet Affiliation History
A1: Affiliation History
A2: Each row is one program-to-league relationship for a season or evidence period. This preserves league moves and conflicting listings without overwriting history.
A3: Affiliation_ID | B3: Program_ID | C3: Original_Record_ID | D3: League_ID | E3: League_Name | F3: Season | G3: Organization_Name_As_Recorded | H3: Primary_County | I3: Municipality_or_Area | J3: Evidence_Status | K3: Current_Affiliation_Flag | L3: Source_Reference | M3: Source_URL | N3: Notes
A4: A001 | B4: P062 | C4: O001 | D4: L001 | E4: South Jersey Independent Youth Football Association | F4: 2026 | G4: Rancocas Valley Hurricanes | H4: Burlington | I4: Rancocas Valley / Lumberton area | J4: Current / verified from 2026 SJIYFA schedule | K4: Yes | L4: SJIYFA 2026 schedule + RV Hurricanes official site | M4: https://www.sjiyfa.org/schedule.php?group=2&township=0&type=0&week=0&weight=0 | N4: Current 2026 SJIYFA schedule and RV Hurricanes site confirm affiliation; SJIYFA field directory also lists RV fields.
A5: A002 | B5: P056 | C5: O002 | D5: L001 | E5: South Jersey Independent Youth Football Association | F5: 2026 | G5: Burlington City | H5: Burlington | I5: Burlington City | J5: Current / verified from 2026 SJIYFA schedule | K5: Yes | L5: SJIYFA 2026 schedule and field directory | M5: https://www.sjiyfa.org/schedule.php?group=2&township=0&type=0&week=0&weight=0 | N5: Current 2026 SJIYFA schedule confirms Burlington City after recent league move.
A6: A003 | B6: P003 | C6: O003 | D6: L002 | E6: Tri-County United Football League | F6: 2026 | G6: Atlantic City | H6: Atlantic | I6: Atlantic City | J6: Current / verified from 2026 TCUFL organization page | K6: Yes | L6: TCUFL 2026 Organizations | M6: https://tcufl.org/organizations.php
A7: A004 | B7: P013 | C7: O004 | D7: L002 | E7: Tri-County United Football League | F7: 2026 | G7: Mays Landing | H7: Atlantic | I7: Mays Landing | J7: Current / verified from 2026 TCUFL organization page | K7: Yes | L7: TCUFL 2026 Organizations | M7: https://tcufl.org/organizations.php
A8: A005 | B8: P015 | C8: O005 | D8: L002 | E8: Tri-County United Football League | F8: 2026 | G8: Pleasantville | H8: Atlantic | I8: Pleasantville | J8: Current / verified from 2026 TCUFL organization page | K8: Yes | L8: TCUFL 2026 Organizations | M8: https://tcufl.org/organizations.php
A9: A006 | B9: P056 | C9: O006 | D9: L002 | E9: Tri-County United Football League | F9: 2026 | G9: Burlington City | H9: Burlington | I9: Burlington City | J9: 2026 TCUFL page / conflicts with current SJIYFA schedule | K9: Verify | L9: TCUFL 2026 Organizations | M9: https://tcufl.org/organizations.php | N9: TCUFL 2026 organization directory lists this program, but current 2026 SJIYFA schedule also lists it. Treat affiliation as unresolved until program/league confirmation.
A10: A007 | B10: P066 | C10: O007 | D10: L002 | E10: Tri-County United Football League | F10: 2026 | G10: Camden | H10: Camden | I10: Camden | J10: Current / verified from 2026 TCUFL organization page | K10: Yes | L10: TCUFL 2026 Organizations | M10: https://tcufl.org/organizations.php
A11: A008 | B11: P067 | C11: O008 | D11: L002 | E11: Tri-County United Football League | F11: 2026 | G11: Centerville | H11: Camden | I11: Centerville | J11: Current / verified from 2026 TCUFL organization page | K11: Yes | L11: TCUFL 2026 Organizations | M11: https://tcufl.org/organizations.php
A12: A009 | B12: P069 | C12: O009 | D12: L002 | E12: Tri-County United Football League | F12: 2026 | G12: Gloucester Township | H12: Camden | I12: Gloucester Township | J12: Current / verified from 2026 TCUFL organization page | K12: Yes | L12: TCUFL 2026 Organizations | M12: https://tcufl.org/organizations.php
A13: A010 | B13: P071 | C13: O010 | D13: L002 | E13: Tri-County United Football League | F13: 2026 | G13: Lindenwold | H13: Camden | I13: Lindenwold | J13: Current / verified from 2026 TCUFL organization page | K13: Yes | L13: TCUFL 2026 Organizations | M13: https://tcufl.org/organizations.php
A14: A011 | B14: P073 | C14: O011 | D14: L002 | E14: Tri-County United Football League | F14: 2026 | G14: Sterling | H14: Camden | I14: Sterling | J14: Current / verified from 2026 TCUFL organization page | K14: Yes | L14: TCUFL 2026 Organizations | M14: https://tcufl.org/organizations.php
A15: A012 | B15: P074 | C15: O012 | D15: L002 | E15: Tri-County United Football League | F15: 2026 | G15: Whitman Park | H15: Camden | I15: Whitman Park | J15: Current / verified from 2026 TCUFL organization page | K15: Yes | L15: TCUFL 2026 Organizations | M15: https://tcufl.org/organizations.php
A16: A013 | B16: P075 | C16: O013 | D16: L002 | E16: Tri-County United Football League | F16: Recent / pre-2026 | G16: Winslow Elite | H16: Camden | I16: Winslow Elite | J16: Recent / not listed on 2026 TCUFL organization page | K16: No | L16: Earlier TCUFL material; compared with 2026 organization directory | M16: https://tcufl.org/organizations.php | N16: Not on official 2026 TCUFL organization directory; retain as recent/historical until exact transition is established.
A17: A014 | B17: P081 | C17: O014 | D17: L002 | E17: Tri-County United Football League | F17: 2026 | G17: Bridgeton | H17: Cumberland | I17: Bridgeton | J17: Current / verified from 2026 TCUFL organization page | K17: Yes | L17: TCUFL 2026 Organizations | M17: https://tcufl.org/organizations.php
A18: A015 | B18: P082 | C18: O015 | D18: L002 | E18: Tri-County United Football League | F18: 2026 | G18: Holly City | H18: Cumberland | I18: Millville | J18: Current / verified from 2026 TCUFL organization page | K18: Yes | L18: TCUFL 2026 Organizations | M18: https://tcufl.org/organizations.php
A19: A016 | B19: P084 | C19: O016 | D19: L002 | E19: Tri-County United Football League | F19: 2026 | G19: Vineland Youth Football (Wolfpack) | H19: Cumberland | I19: Vineland | J19: Current / verified from 2026 TCUFL organization page | K19: Yes | L19: TCUFL 2026 Organizations | M19: https://tcufl.org/organizations.php
A20: A017 | B20: P103 | C20: O017 | D20: L002 | E20: Tri-County United Football League | F20: 2026 | G20: Clayton | H20: Gloucester | I20: Clayton | J20: Current / verified from 2026 TCUFL organization page | K20: Yes | L20: TCUFL 2026 Organizations | M20: https://tcufl.org/organizations.php
A21: A018 | B21: P104 | C21: O018 | D21: L002 | E21: Tri-County United Football League | F21: 2026 | G21: Delsea | H21: Gloucester | I21: Delsea | J21: Current / verified from 2026 TCUFL organization page | K21: Yes | L21: TCUFL 2026 Organizations | M21: https://tcufl.org/organizations.php
A22: A019 | B22: P105 | C22: O019 | D22: L002 | E22: Tri-County United Football League | F22: 2026 | G22: Deptford | H22: Gloucester | I22: Deptford | J22: Current / verified from 2026 TCUFL organization page | K22: Yes | L22: TCUFL 2026 Organizations | M22: https://tcufl.org/organizations.php
A23: A020 | B23: P106 | C23: O020 | D23: L002 | E23: Tri-County United Football League | F23: 2026 | G23: Glassboro | H23: Gloucester | I23: Glassboro | J23: Current / verified from 2026 TCUFL organization page | K23: Yes | L23: TCUFL 2026 Organizations | M23: https://tcufl.org/organizations.php
A24: A021 | B24: P107 | C24: O021 | D24: L002 | E24: Tri-County United Football League | F24: 2026 | G24: Kingsway | H24: Gloucester | I24: Kingsway | J24: Current / verified from 2026 TCUFL organization page | K24: Yes | L24: TCUFL 2026 Organizations | M24: https://tcufl.org/organizations.php
A25: A022 | B25: P108 | C25: O022 | D25: L002 | E25: Tri-County United Football League | F25: 2026 | G25: Monroe | H25: Gloucester | I25: Monroe | J25: Current / verified from 2026 TCUFL organization page | K25: Yes | L25: TCUFL 2026 Organizations | M25: https://tcufl.org/organizations.php
A26: A023 | B26: P109 | C26: O023 | D26: L002 | E26: Tri-County United Football League | F26: Recent / pre-2026 | G26: Paulsboro | H26: Gloucester | I26: Paulsboro | J26: Recent / not listed on 2026 TCUFL organization page | K26: No | L26: Earlier TCUFL material; compared with 2026 organization directory | M26: https://tcufl.org/organizations.php | N26: Not on official 2026 TCUFL organization directory; retain as recent/historical until exact transition is established.
A27: A024 | B27: P112 | C27: O024 | D27: L002 | E27: Tri-County United Football League | F27: 2026 | G27: Woodbury | H27: Gloucester | I27: Woodbury | J27: Current / verified from 2026 TCUFL organization page | K27: Yes | L27: TCUFL 2026 Organizations | M27: https://tcufl.org/organizations.php
A28: A025 | B28: P174 | C28: O025 | D28: L002 | E28: Tri-County United Football League | F28: Recent / pre-2026 | G28: Penns Grove | H28: Salem | I28: Penns Grove | J28: Recent / not listed on 2026 TCUFL organization page | K28: No | L28: Earlier TCUFL material; compared with 2026 organization directory | M28: https://tcufl.org/organizations.php | N28: Not on official 2026 TCUFL organization directory; retain as recent/historical until exact transition is established.
A29: A026 | B29: P175 | C29: O026 | D29: L002 | E29: Tri-County United Football League | F29: 2026 | G29: Pennsville | H29: Salem | I29: Pennsville | J29: Current / verified from 2026 TCUFL organization page | K29: Yes | L29: TCUFL 2026 Organizations | M29: https://tcufl.org/organizations.php
A30: A027 | B30: P177 | C30: O027 | D30: L002 | E30: Tri-County United Football League | F30: 2026 | G30: Salem | H30: Salem | I30: Salem | J30: Current / verified from 2026 TCUFL organization page | K30: Yes | L30: TCUFL 2026 Organizations | M30: https://tcufl.org/organizations.php
A31: A028 | B31: P055 | C31: O028 | D31: L003 | E31: West Jersey Youth Football League | F31: 2026 | G31: Bordentown | H31: Burlington | I31: Bordentown | J31: Current / verified from official WJYFL teams page | K31: Yes | L31: WJYFL official Teams page | M31: https://www.westjerseyyouthfootball.com/teams
A32: A029 | B32: P057 | C32: O029 | D32: L003 | E32: West Jersey Youth Football League | F32: 2026 | G32: Florence | H32: Burlington | I32: Florence | J32: Current / verified from official WJYFL teams page | K32: Yes | L32: WJYFL official Teams page | M32: https://www.westjerseyyouthfootball.com/teams
A33: A030 | B33: P059 | C33: O030 | D33: L003 | E33: West Jersey Youth Football League | F33: 2026 | G33: Northern Burlington | H33: Burlington | I33: Northern Burlington | J33: Current / verified from official WJYFL teams page | K33: Yes | L33: WJYFL official Teams page | M33: https://www.westjerseyyouthfootball.com/teams
A34: A031 | B34: P061 | C34: O031 | D34: L003 | E34: West Jersey Youth Football League | F34: 2026 | G34: Pemberton | H34: Burlington | I34: Pemberton | J34: Current / verified from official WJYFL teams page | K34: Yes | L34: WJYFL official Teams page | M34: https://www.westjerseyyouthfootball.com/teams
A35: A032 | B35: P060 | C35: O032 | D35: L003 | E35: West Jersey Youth Football League | F35: 2026 | G35: Palmyra | H35: Burlington | I35: Palmyra | J35: Current / verified from official WJYFL teams page | K35: Yes | L35: WJYFL official Teams page | M35: https://www.westjerseyyouthfootball.com/teams
A36: A033 | B36: P058 | C36: O033 | D36: L003 | E36: West Jersey Youth Football League | F36: 2026 | G36: Moorestown | H36: Burlington | I36: Moorestown | J36: Current / verified from official WJYFL teams page | K36: Yes | L36: WJYFL official Teams page | M36: https://www.westjerseyyouthfootball.com/teams
A37: A034 | B37: P063 | C37: O034 | D37: L003 | E37: West Jersey Youth Football League | F37: 2026 | G37: Riverside | H37: Burlington | I37: Riverside | J37: Current / verified from official WJYFL teams page | K37: Yes | L37: WJYFL official Teams page | M37: https://www.westjerseyyouthfootball.com/teams
A38: A035 | B38: P123 | C38: O035 | D38: L003 | E38: West Jersey Youth Football League | F38: 2026 | G38: Lawrence | H38: Mercer | I38: Lawrence | J38: Current / verified from official WJYFL teams page | K38: Yes | L38: WJYFL official Teams page | M38: https://www.westjerseyyouthfootball.com/teams
A39: A036 | B39: P122 | C39: O036 | D39: L003 | E39: West Jersey Youth Football League | F39: 2026 | G39: Hopewell Valley | H39: Mercer | I39: Hopewell Valley | J39: Current / verified from official WJYFL teams page | K39: Yes | L39: WJYFL official Teams page | M39: https://www.westjerseyyouthfootball.com/teams
A40: A037 | B40: P158 | C40: O037 | D40: L003 | E40: West Jersey Youth Football League | F40: 2026 | G40: New Egypt | H40: Ocean | I40: New Egypt | J40: Current / verified from official WJYFL teams page | K40: Yes | L40: WJYFL official Teams page | M40: https://www.westjerseyyouthfootball.com/teams
...

Sheet Organization Master
A1: Organization Master
A3: Org_ID | B3: League_ID | C3: Organization_Name | D3: Season | E3: Primary_County | F3: Additional_Counties | G3: Municipality_or_Area | H3: Service_Area | I3: High_School_or_Sending_District | J3: Home_Field | K3: Field_Address | L3: NJYASA_Region | M3: Evidence_Status | N3: Source_Reference | O3: Source_URL | P3: Notes | Q3: Program_ID | R3: Current_Affiliation_Flag | S3: Phase1_Review_Flag
A4: O001 | B4: L001 | C4: Rancocas Valley Hurricanes | D4: 2026 | E4: Burlington | G4: Rancocas Valley / Lumberton area | I4: Rancocas Valley Regional High School | J4: Lumberton Field / RVHS | K4: 35 Municipal Dr., Lumberton, NJ 08048 | L4: South | M4: Current / verified from 2026 SJIYFA schedule | N4: SJIYFA 2026 schedule + RV Hurricanes official site | O4: https://www.sjiyfa.org/schedule.php?group=2&township=0&type=0&week=0&weight=0 | P4: Current 2026 SJIYFA schedule and RV Hurricanes site confirm affiliation; SJIYFA field directory also lists RV fields. | Q4: P062 | R4: Yes | S4: Current affiliation supported
A5: O002 | B5: L001 | C5: Burlington City | D5: 2026 | E5: Burlington | G5: Burlington City | J5: Burlington City | K5: 550 High St, Burlington, NJ 08016 | L5: South | M5: Current / verified from 2026 SJIYFA schedule | N5: SJIYFA 2026 schedule and field directory | O5: https://www.sjiyfa.org/schedule.php?group=2&township=0&type=0&week=0&weight=0 | P5: Current 2026 SJIYFA schedule confirms Burlington City after recent league move. | Q5: P056 | R5: Yes | S5: Current affiliation supported
A6: O003 | B6: L002 | C6: Atlantic City | D6: 2026 | E6: Atlantic | G6: Atlantic City | L6: South | M6: Current / verified from 2026 TCUFL organization page | N6: TCUFL 2026 Organizations | O6: https://tcufl.org/organizations.php | Q6: P003 | R6: Yes | S6: Current affiliation supported
A7: O004 | B7: L002 | C7: Mays Landing | D7: 2026 | E7: Atlantic | G7: Mays Landing | L7: South | M7: Current / verified from 2026 TCUFL organization page | N7: TCUFL 2026 Organizations | O7: https://tcufl.org/organizations.php | Q7: P013 | R7: Yes | S7: Current affiliation supported
A8: O005 | B8: L002 | C8: Pleasantville | D8: 2026 | E8: Atlantic | G8: Pleasantville | L8: South | M8: Current / verified from 2026 TCUFL organization page | N8: TCUFL 2026 Organizations | O8: https://tcufl.org/organizations.php | Q8: P015 | R8: Yes | S8: Current affiliation supported
A9: O006 | B9: L002 | C9: Burlington City | D9: 2026 | E9: Burlington | G9: Burlington City | L9: South | M9: 2026 TCUFL page / conflicts with current SJIYFA schedule | N9: TCUFL 2026 Organizations | O9: https://tcufl.org/organizations.php | P9: TCUFL 2026 organization directory lists this program, but current 2026 SJIYFA schedule also lists it. Treat affiliation as unresolved until program/league confirmation. | Q9: P056 | R9: Verify | S9: Conflicting/partial current evidence
A10: O007 | B10: L002 | C10: Camden | D10: 2026 | E10: Camden | G10: Camden | L10: South | M10: Current / verified from 2026 TCUFL organization page | N10: TCUFL 2026 Organizations | O10: https://tcufl.org/organizations.php | Q10: P066 | R10: Yes | S10: Current affiliation supported
A11: O008 | B11: L002 | C11: Centerville | D11: 2026 | E11: Camden | G11: Centerville | L11: South | M11: Current / verified from 2026 TCUFL organization page | N11: TCUFL 2026 Organizations | O11: https://tcufl.org/organizations.php | Q11: P067 | R11: Yes | S11: Current affiliation supported
A12: O009 | B12: L002 | C12: Gloucester Township | D12: 2026 | E12: Camden | G12: Gloucester Township | L12: South | M12: Current / verified from 2026 TCUFL organization page | N12: TCUFL 2026 Organizations | O12: https://tcufl.org/organizations.php | Q12: P069 | R12: Yes | S12: Current affiliation supported
A13: O010 | B13: L002 | C13: Lindenwold | D13: 2026 | E13: Camden | G13: Lindenwold | L13: South | M13: Current / verified from 2026 TCUFL organization page | N13: TCUFL 2026 Organizations | O13: https://tcufl.org/organizations.php | Q13: P071 | R13: Yes | S13: Multiple current affiliations - verify structure
A14: O011 | B14: L002 | C14: Sterling | D14: 2026 | E14: Camden | G14: Sterling | L14: South | M14: Current / verified from 2026 TCUFL organization page | N14: TCUFL 2026 Organizations | O14: https://tcufl.org/organizations.php | Q14: P073 | R14: Yes | S14: Current affiliation supported
A15: O012 | B15: L002 | C15: Whitman Park | D15: 2026 | E15: Camden | G15: Whitman Park | L15: South | M15: Current / verified from 2026 TCUFL organization page | N15: TCUFL 2026 Organizations | O15: https://tcufl.org/organizations.php | Q15: P074 | R15: Yes | S15: Current affiliation supported
A16: O013 | B16: L002 | C16: Winslow Elite | D16: Recent / pre-2026 | E16: Camden | G16: Winslow Elite | L16: South | M16: Recent / not listed on 2026 TCUFL organization page | N16: Earlier TCUFL material; compared with 2026 organization directory | O16: https://tcufl.org/organizations.php | P16: Not on official 2026 TCUFL organization directory; retain as recent/historical until exact transition is established. | Q16: P075 | R16: No | S16: Historical/prior affiliation
A17: O014 | B17: L002 | C17: Bridgeton | D17: 2026 | E17: Cumberland | G17: Bridgeton | L17: South | M17: Current / verified from 2026 TCUFL organization page | N17: TCUFL 2026 Organizations | O17: https://tcufl.org/organizations.php | Q17: P081 | R17: Yes | S17: Current affiliation supported
A18: O015 | B18: L002 | C18: Holly City | D18: 2026 | E18: Cumberland | G18: Millville | L18: South | M18: Current / verified from 2026 TCUFL organization page | N18: TCUFL 2026 Organizations | O18: https://tcufl.org/organizations.php | Q18: P082 | R18: Yes | S18: Current affiliation supported
A19: O016 | B19: L002 | C19: Vineland Youth Football (Wolfpack) | D19: 2026 | E19: Cumberland | G19: Vineland | L19: South | M19: Current / verified from 2026 TCUFL organization page | N19: TCUFL 2026 Organizations | O19: https://tcufl.org/organizations.php | Q19: P084 | R19: Yes | S19: Current affiliation supported
A20: O017 | B20: L002 | C20: Clayton | D20: 2026 | E20: Gloucester | G20: Clayton | L20: South | M20: Current / verified from 2026 TCUFL organization page | N20: TCUFL 2026 Organizations | O20: https://tcufl.org/organizations.php | Q20: P103 | R20: Yes | S20: Current affiliation supported
A21: O018 | B21: L002 | C21: Delsea | D21: 2026 | E21: Gloucester | G21: Delsea | L21: South | M21: Current / verified from 2026 TCUFL organization page | N21: TCUFL 2026 Organizations | O21: https://tcufl.org/organizations.php | Q21: P104 | R21: Yes | S21: Current affiliation supported
A22: O019 | B22: L002 | C22: Deptford | D22: 2026 | E22: Gloucester | G22: Deptford | L22: South | M22: Current / verified from 2026 TCUFL organization page | N22: TCUFL 2026 Organizations | O22: https://tcufl.org/organizations.php | Q22: P105 | R22: Yes | S22: Current affiliation supported
A23: O020 | B23: L002 | C23: Glassboro | D23: 2026 | E23: Gloucester | G23: Glassboro | L23: South | M23: Current / verified from 2026 TCUFL organization page | N23: TCUFL 2026 Organizations | O23: https://tcufl.org/organizations.php | Q23: P106 | R23: Yes | S23: Current affiliation supported
A24: O021 | B24: L002 | C24: Kingsway | D24: 2026 | E24: Gloucester | G24: Kingsway | L24: South | M24: Current / verified from 2026 TCUFL organization page | N24: TCUFL 2026 Organizations | O24: https://tcufl.org/organizations.php | Q24: P107 | R24: Yes | S24: Current affiliation supported
A25: O022 | B25: L002 | C25: Monroe | D25: 2026 | E25: Gloucester | G25: Monroe | L25: South | M25: Current / verified from 2026 TCUFL organization page | N25: TCUFL 2026 Organizations | O25: https://tcufl.org/organizations.php | Q25: P108 | R25: Yes | S25: Current affiliation supported
A26: O023 | B26: L002 | C26: Paulsboro | D26: Recent / pre-2026 | E26: Gloucester | G26: Paulsboro | L26: South | M26: Recent / not listed on 2026 TCUFL organization page | N26: Earlier TCUFL material; compared with 2026 organization directory | O26: https://tcufl.org/organizations.php | P26: Not on official 2026 TCUFL organization directory; retain as recent/historical until exact transition is established. | Q26: P109 | R26: No | S26: Historical/prior affiliation
A27: O024 | B27: L002 | C27: Woodbury | D27: 2026 | E27: Gloucester | G27: Woodbury | L27: South | M27: Current / verified from 2026 TCUFL organization page | N27: TCUFL 2026 Organizations | O27: https://tcufl.org/organizations.php | Q27: P112 | R27: Yes | S27: Current affiliation supported
A28: O025 | B28: L002 | C28: Penns Grove | D28: Recent / pre-2026 | E28: Salem | G28: Penns Grove | L28: South | M28: Recent / not listed on 2026 TCUFL organization page | N28: Earlier TCUFL material; compared with 2026 organization directory | O28: https://tcufl.org/organizations.php | P28: Not on official 2026 TCUFL organization directory; retain as recent/historical until exact transition is established. | Q28: P174 | R28: No | S28: Historical/prior affiliation
A29: O026 | B29: L002 | C29: Pennsville | D29: 2026 | E29: Salem | G29: Pennsville | L29: South | M29: Current / verified from 2026 TCUFL organization page | N29: TCUFL 2026 Organizations | O29: https://tcufl.org/organizations.php | Q29: P175 | R29: Yes | S29: Current affiliation supported
A30: O027 | B30: L002 | C30: Salem | D30: 2026 | E30: Salem | G30: Salem | L30: South | M30: Current / verified from 2026 TCUFL organization page | N30: TCUFL 2026 Organizations | O30: https://tcufl.org/organizations.php | Q30: P177 | R30: Yes | S30: Current affiliation supported
A31: O028 | B31: L003 | C31: Bordentown | D31: 2026 | E31: Burlington | G31: Bordentown | J31: Bordentown Bulldogs | K31: 50 Dunns Mill Rd., Bordentown, NJ | L31: South | M31: Current / verified from official WJYFL teams page | N31: WJYFL official Teams page | O31: https://www.westjerseyyouthfootball.com/teams | Q31: P055 | R31: Yes | S31: Current affiliation supported
A32: O029 | B32: L003 | C32: Florence | D32: 2026 | E32: Burlington | G32: Florence | J32: Florence Flashes | K32: 875 Summer St., Florence, NJ | L32: South | M32: Current / verified from official WJYFL teams page | N32: WJYFL official Teams page | O32: https://www.westjerseyyouthfootball.com/teams | Q32: P057 | R32: Yes | S32: Current affiliation supported
A33: O030 | B33: L003 | C33: Northern Burlington | D33: 2026 | E33: Burlington | G33: Northern Burlington | J33: Northern Burlington Greyhounds | K33: 180/160 Mansfield Rd., East Mansfield, NJ | L33: South | M33: Current / verified from official WJYFL teams page | N33: WJYFL official Teams page | O33: https://www.westjerseyyouthfootball.com/teams | Q33: P059 | R33: Yes | S33: Current affiliation supported
A34: O031 | B34: L003 | C34: Pemberton | D34: 2026 | E34: Burlington | G34: Pemberton | J34: Pemberton Hornets | K34: 1 Anderson Rd., Pemberton, NJ | L34: South | M34: Current / verified from official WJYFL teams page | N34: WJYFL official Teams page | O34: https://www.westjerseyyouthfootball.com/teams | Q34: P061 | R34: Yes | S34: Current affiliation supported
A35: O032 | B35: L003 | C35: Palmyra | D35: 2026 | E35: Burlington | G35: Palmyra | J35: Palmyra Panthers | K35: Broad & Park Ave., Palmyra, NJ | L35: South | M35: Current / verified from official WJYFL teams page | N35: WJYFL official Teams page | O35: https://www.westjerseyyouthfootball.com/teams | Q35: P060 | R35: Yes | S35: Current affiliation supported
A36: O033 | B36: L003 | C36: Moorestown | D36: 2026 | E36: Burlington | G36: Moorestown | J36: Moorestown Junior Quakers | K36: 1248 N. Church St., Moorestown, NJ | L36: South | M36: Current / verified from official WJYFL teams page | N36: WJYFL official Teams page | O36: https://www.westjerseyyouthfootball.com/teams | Q36: P058 | R36: Yes | S36: Current affiliation supported
A37: O034 | B37: L003 | C37: Riverside | D37: 2026 | E37: Burlington | G37: Riverside | J37: Riverside Rams | K37: 112 E. Washington St., Riverside, NJ | L37: South | M37: Current / verified from official WJYFL teams page | N37: WJYFL official Teams page | O37: https://www.westjerseyyouthfootball.com/teams | Q37: P063 | R37: Yes | S37: Current affiliation supported
A38: O035 | B38: L003 | C38: Lawrence | D38: 2026 | E38: Mercer | G38: Lawrence | J38: Lawrence Cardinals | K38: 100 Dave Nevius Way, Lawrence, NJ | L38: Central | M38: Current / verified from official WJYFL teams page | N38: WJYFL official Teams page | O38: https://www.westjerseyyouthfootball.com/teams | Q38: P123 | R38: Yes | S38: Current affiliation supported
A39: O036 | B39: L003 | C39: Hopewell Valley | D39: 2026 | E39: Mercer | G39: Hopewell Valley | J39: Hopewell Valley Bulldogs | K39: 201 Washington Crossing-Pennington Rd., Titusville, NJ | L39: Central | M39: Current / verified from official WJYFL teams page | N39: WJYFL official Teams page | O39: https://www.westjerseyyouthfootball.com/teams | Q39: P122 | R39: Yes | S39: Current affiliation supported
A40: O037 | B40: L003 | C40: New Egypt | D40: 2026 | E40: Ocean | G40: New Egypt | J40: New Egypt Warriors | K40: 24 Brindletown Rd., New Egypt, NJ | L40: Central | M40: Current / verified from official WJYFL teams page | N40: WJYFL official Teams page | O40: https://www.westjerseyyouthfootball.com/teams | Q40: P158 | R40: Yes | S40: Current affiliation supported
A41: O038 | B41: L003 | C41: Haddon Township | D41: 2026 | E41: Camden | G41: Haddon Township | J41: Haddon Twp Hawks | K41: 350 W. Crystal Lake Ave., Haddonfield, NJ | L41: South | M41: Current / verified from official WJYFL teams page | N41: WJYFL official Teams page | O41: https://www.westjerseyyouthfootball.com/teams | Q41: P070 | R41: Yes | S41: Current affiliation supported
...

Sheet League Master
A1: League Master
A3: League_ID | B3: League_Name | C3: Acronym | D3: Governing_Body | E3: Status | F3: Latest_Season_Verified | G3: Primary_Counties | H3: NJYASA_Regions | I3: Territory_Model | J3: Competition_Model | K3: Known_Age_Structure | L3: Player_Counts_Available | M3: Boundary_Data_Available | N3: Field_Data_Available | O3: Evidence_Quality | P3: Notes
A4: L001 | B4: South Jersey Independent Youth Football Association | C4: SJIYFA | D4: Independent | E4: Active / current | F4: 2026 | G4: Burlington; South Jersey | H4: South | I4: Sending-district / community territory | J4: League structure; current move evidence | K4: Youth tackle / age-weight | L4: Partial | M4: Partial | N4: Partial | O4: Medium | P4: Burlington City reported as a recent 2026 move into SJIYFA; RV Hurricanes known member from project context.
A5: L002 | B5: Tri-County United Football League | C5: TCUFL South | D5: Independent | E5: Active / current | F5: 2026 | G5: Atlantic; Burlington; Camden; Cumberland; Gloucester; Salem | H5: South | I5: Community / municipal | J5: Multi-county competition | K5: Multiple age/weight groups | L5: Unknown | M5: Partial | N5: Partial | O5: High | P5: 2026 organization list documented; Burlington City appears in older/current-source list but user reports it moved to SJIYFA in 2026.
A6: L003 | B6: West Jersey Youth Football League | C6: WJYFL | D6: Independent | E6: Active / current | F6: 2026 | G6: Burlington; Mercer; Ocean; Camden; Gloucester | H6: South; Central | I6: Community / program | J6: North / South divisions | K6: Youth tackle | L6: Unknown | M6: Unknown | N6: Yes | O6: High | P6: 2026 league home page and team/field evidence reviewed.
A7: L004 | B7: Cape Atlantic Junior Football League | C7: CAJFL | D7: Independent | E7: Active / current | F7: 2025-2026 | G7: Atlantic; Cape May; Cumberland | H7: South | I7: Explicit franchise territories; some school-sending geography | J7: League competition | K7: Taxi; Pee Wee; JV; Varsity | L7: Partial potential | M7: Yes | N7: Yes | O7: High | P7: Bylaws define territories and roster/eligibility rules.
A8: L005 | B8: Jersey Shore Youth Football League | C8: JSYFL | D8: Independent | E8: Active / current | F8: 2025 exact / 2026 site | G8: Atlantic; Cape May | H8: South | I8: Franchise boundaries with board-approved out-of-franchise exceptions | J8: Mostly Atlantic County with adjacent-county crossover | K8: Taxi; Peewee; Jayvee; Varsity | L8: Application requests counts | M8: Yes | N8: Yes | O8: High | P8: 2025 nine-team schedule plus 2026 site, franchise application, waiver form, coach pledge.
A9: L006 | B9: New Jersey American Youth Football - Jersey Shore Conference | C9: NJAYF | D9: American Youth Football | E9: Active / current | F9: 2026 | G9: Monmouth; Ocean; Middlesex; Hunterdon; Union; other Central NJ | H9: Central | I9: Franchise territories often aligned with public-high-school geography | J9: Annual division alignment; player pool / nearby placement | K9: Flag through 14U | L9: Partial potential | M9: Yes | N9: Yes | O9: High | P9: Extensive 2026 governance material reviewed.
A10: L007 | B10: New Jersey Suburban Youth Football League | C10: NJSYFL | D10: Independent | E10: Active / current | F10: 2026 | G10: Somerset; Morris; Essex; Union; Middlesex; Hunterdon | H10: North; Central | I10: Town/community residency | J10: A/B/C-style competitive levels and age/weight structure | K10: Flag / F through A | L10: Unknown | M10: Partial | N10: Partial | O10: High | P10: Current participating-program material and rules reviewed.
A11: L008 | B11: Morris County Youth Football League | C11: MCYFL | D11: Independent | E11: Active / current | F11: 2025-2026 | G11: Morris; Passaic; Sussex; Warren; Somerset | H11: North; Central | I11: Approved town/township territories; sending-school district can resolve residency | J11: Freedom / National / American based partly on size and performance | K11: Multiple grade/age levels; girls flag | L11: Partial potential | M11: Yes | N11: Yes | O11: High | P11: Territory maps and public-school systems are explicit in application/bylaws.
A12: L009 | B12: Meadowlands Football League | C12: MFL | D12: Independent | E12: Active / current | F12: 2026 | G12: Bergen; Hudson; Passaic | H12: North | I12: Town residency | J12: North / South geographic divisions with crossover games | K12: Mighty Mite; Pee Wee; Junior; Senior | L12: Unknown | M12: Partial | N12: Partial | O12: High | P12: Current team page and bylaws reviewed.
